import React from 'react';
import { render, screen, fireEvent } from '@testing-library/react';
import { vi, describe, it, expect } from 'vitest';
import ErrorBoundary from '../components/ErrorBoundary';

const ThrowError = ({ shouldThrow }) => {
  if (shouldThrow) {
    throw new Error('Test error');
  }
  return <div>No error</div>;
};

describe('ErrorBoundary', () => {
  beforeEach(() => {
    vi.clearAllMocks();
  });

  it('renders children when no error occurs', () => {
    render(
      <ErrorBoundary>
        <ThrowError shouldThrow={false} />
      </ErrorBoundary>
    );

    expect(screen.getByText('No error')).toBeInTheDocument();
  });

  it('renders error UI when an error occurs', () => {
    render(
      <ErrorBoundary>
        <ThrowError shouldThrow={true} />
      </ErrorBoundary>
    );

    expect(screen.getByTestId('error-boundary')).toBeInTheDocument();
    expect(screen.getByText('Something went wrong')).toBeInTheDocument();
    expect(screen.getByText('Test error')).toBeInTheDocument();
  });

  it('resets error state when try again is clicked', () => {
    const { rerender } = render(
      <ErrorBoundary>
        <ThrowError shouldThrow={true} />
      </ErrorBoundary>
    );

    const tryAgainButton = screen.getByTestId('error-retry-button');
    fireEvent.click(tryAgainButton);

    rerender(
      <ErrorBoundary>
        <ThrowError shouldThrow={false} />
      </ErrorBoundary>
    );

    expect(screen.getByText('No error')).toBeInTheDocument();
  });

  it('calls onError prop when an error occurs', () => {
    const onError = vi.fn();
    render(
      <ErrorBoundary onError={onError}>
        <ThrowError shouldThrow={true} />
      </ErrorBoundary>
    );

    expect(onError).toHaveBeenCalledWith(expect.any(Error), expect.any(Object));
  });
}); 