{
  "timestamp": "2025-01-19T13:10:06.393938",
  "tests": {
    "redis_failover": {
      "status": "success",
      "operations_test": true,
      "replication_role": "master",
      "connected_slaves": 0
    },
    "backups": {
      "status": "success",
      "redis_backup": true,
      "supabase_backup": false,
      "redis_dump_exists": false,
      "supabase_dump_exists": false
    },
    "monitoring": {
      "status": "failed",
      "error": "HTTPConnectionPool(host='localhost', port=9090): Max retries exceeded with url: /api/v1/query?query=up (Caused by NewConnectionError('<urllib3.connection.HTTPConnection object at 0x71af1ff5b0e0>: Failed to establish a new connection: [Errno 111] Connection refused'))"
    },
    "security": {
      "status": "success",
      "security_checks": {
        "ssl_enabled": false,
        "api_key_required": true,
        "jwt_secret_configured": true,
        "cors_configured": true
      },
      "rate_limiting_working": false
    }
  },
  "issues": [
    "Monitoring check failed: HTTPConnectionPool(host='localhost', port=9090): Max retries exceeded with url: /api/v1/query?query=up (Caused by NewConnectionError('<urllib3.connection.HTTPConnection object at 0x71af1ff5b0e0>: Failed to establish a new connection: [Errno 111] Connection refused'))"
  ]
}